2023-05-29 08:04:28 WARNING (SyncWorker_0) [homeassistant.loader] We found a custom integration hacs which has not been tested by Home Assistant. This component might cause stability problems, be sure to disable it if you experience issues with Home Assistant
2023-05-29 08:04:29 WARNING (MainThread) [homeassistant.components.http] The 'base_url' option near /config/configuration.yaml:8 is deprecated, please remove it from your configuration
2023-05-29 08:04:33 ERROR (MainThread) [homeassistant.helpers.template] Template variable error: 'None' has no attribute 'attributes' when rendering 'IPS Device {{ states.sensor.togethome_position_data.attributes.device_data[0]["device_id"] }} Name'
2023-05-29 08:04:33 ERROR (MainThread) [homeassistant.helpers.template] Template variable error: 'None' has no attribute 'attributes' when rendering 'IPS Device {{ states.sensor.togethome_position_data.attributes.device_data[0]["device_id"] }} State'
2023-05-29 08:04:33 ERROR (MainThread) [homeassistant.helpers.template] Template variable error: 'None' has no attribute 'attributes' when rendering 'IPS Device {{ states.sensor.togethome_position_data.attributes.device_data[0]["device_id"] }} Space ID'
2023-05-29 08:04:33 ERROR (MainThread) [homeassistant.helpers.template] Template variable error: 'None' has no attribute 'attributes' when rendering 'IPS Device {{ states.sensor.togethome_position_data.attributes.device_data[0]["device_id"] }} Space Name'
2023-05-29 08:04:33 ERROR (MainThread) [homeassistant.helpers.template] Template variable error: 'None' has no attribute 'attributes' when rendering 'IPS Device {{ states.sensor.togethome_position_data.attributes.device_data[0]["device_id"] }} Space Size X'
2023-05-29 08:04:33 ERROR (MainThread) [homeassistant.helpers.template] Template variable error: 'None' has no attribute 'attributes' when rendering 'IPS Device {{ states.sensor.togethome_position_data.attributes.device_data[0]["device_id"] }} Space Size Y'
2023-05-29 08:04:33 ERROR (MainThread) [homeassistant.helpers.template] Template variable error: 'None' has no attribute 'attributes' when rendering 'IPS Device {{ states.sensor.togethome_position_data.attributes.device_data[0]["device_id"] }} Position X'
2023-05-29 08:04:33 ERROR (MainThread) [homeassistant.helpers.template] Template variable error: 'None' has no attribute 'attributes' when rendering 'IPS Device {{ states.sensor.togethome_position_data.attributes.device_data[0]["device_id"] }} Position Y'
2023-05-29 08:04:33 ERROR (MainThread) [homeassistant.helpers.template] Template variable error: 'None' has no attribute 'attributes' when rendering 'IPS Device {{ states.sensor.togethome_position_data.attributes.device_data[0]["device_id"] }} Position Ratio X'
2023-05-29 08:04:33 ERROR (MainThread) [homeassistant.helpers.template] Template variable error: 'None' has no attribute 'attributes' when rendering 'IPS Device {{ states.sensor.togethome_position_data.attributes.device_data[0]["device_id"] }} Position Ratio Y'
2023-05-29 08:04:33 ERROR (MainThread) [homeassistant.helpers.template] Template variable error: 'None' has no attribute 'attributes' when rendering 'IPS Device {{ states.sensor.togethome_position_data.attributes.device_data[0]["device_id"] }} Scan Time'
2023-05-29 08:04:33 ERROR (MainThread) [homeassistant.helpers.template] Template variable error: 'None' has no attribute 'attributes' when rendering 'IPS Device {{ states.sensor.togethome_position_data.attributes.device_data[1]["device_id"] }} Name'
2023-05-29 08:04:33 ERROR (MainThread) [homeassistant.helpers.template] Template variable error: 'None' has no attribute 'attributes' when rendering 'IPS Device {{ states.sensor.togethome_position_data.attributes.device_data[1]["device_id"] }} State'
2023-05-29 08:04:33 ERROR (MainThread) [homeassistant.helpers.template] Template variable error: 'None' has no attribute 'attributes' when rendering 'IPS Device {{ states.sensor.togethome_position_data.attributes.device_data[1]["device_id"] }} Space ID'
2023-05-29 08:04:33 ERROR (MainThread) [homeassistant.helpers.template] Template variable error: 'None' has no attribute 'attributes' when rendering 'IPS Device {{ states.sensor.togethome_position_data.attributes.device_data[1]["device_id"] }} Space Name'
2023-05-29 08:04:33 ERROR (MainThread) [homeassistant.helpers.template] Template variable error: 'None' has no attribute 'attributes' when rendering 'IPS Device {{ states.sensor.togethome_position_data.attributes.device_data[1]["device_id"] }} Space Size X'
2023-05-29 08:04:33 ERROR (MainThread) [homeassistant.helpers.template] Template variable error: 'None' has no attribute 'attributes' when rendering 'IPS Device {{ states.sensor.togethome_position_data.attributes.device_data[1]["device_id"] }} Space Size Y'
2023-05-29 08:04:33 ERROR (MainThread) [homeassistant.helpers.template] Template variable error: 'None' has no attribute 'attributes' when rendering 'IPS Device {{ states.sensor.togethome_position_data.attributes.device_data[1]["device_id"] }} Position X'
2023-05-29 08:04:33 ERROR (MainThread) [homeassistant.helpers.template] Template variable error: 'None' has no attribute 'attributes' when rendering 'IPS Device {{ states.sensor.togethome_position_data.attributes.device_data[1]["device_id"] }} Position Y'
2023-05-29 08:04:33 ERROR (MainThread) [homeassistant.helpers.template] Template variable error: 'None' has no attribute 'attributes' when rendering 'IPS Device {{ states.sensor.togethome_position_data.attributes.device_data[1]["device_id"] }} Position Ratio X'
2023-05-29 08:04:33 ERROR (MainThread) [homeassistant.helpers.template] Template variable error: 'None' has no attribute 'attributes' when rendering 'IPS Device {{ states.sensor.togethome_position_data.attributes.device_data[1]["device_id"] }} Position Ratio Y'
2023-05-29 08:04:33 ERROR (MainThread) [homeassistant.helpers.template] Template variable error: 'None' has no attribute 'attributes' when rendering 'IPS Device {{ states.sensor.togethome_position_data.attributes.device_data[1]["device_id"] }} Scan Time'
2023-05-29 08:04:36 WARNING (MainThread) [homeassistant.helpers.frame] Detected integration that accessed discovery_info.__contains__('ssdp_location') instead of discovery_info.upnp.__contains__('ssdp_location') or discovery_info.ssdp_headers.__contains__('ssdp_location'); this will fail in version 2022.6. Please report issue for upnp using this method at homeassistant/components/upnp/device.py, line 78: if ssdp.ATTR_SSDP_LOCATION not in headers:
2023-05-29 08:04:36 WARNING (MainThread) [homeassistant.helpers.frame] Detected integration that accessed discovery_info['ssdp_location'] instead of discovery_info.ssdp_location, discovery_info.upnp['ssdp_location'] or discovery_info.ssdp_headers['ssdp_location']; this will fail in version 2022.6. Please report issue for upnp using this method at homeassistant/components/upnp/device.py, line 81: location = headers[ssdp.ATTR_SSDP_LOCATION]
2023-05-29 08:04:49 ERROR (MainThread) [homeassistant] Error doing job: Task exception was never retrieved
Traceback (most recent call last):
  File "/usr/src/homeassistant/homeassistant/helpers/update_coordinator.py", line 134, in _handle_refresh_interval
    await self._async_refresh(log_failures=True, scheduled=True)
  File "/usr/src/homeassistant/homeassistant/helpers/update_coordinator.py", line 265, in _async_refresh
    update_callback()
  File "/usr/src/homeassistant/homeassistant/components/xiaomi_miio/fan.py", line 956, in _handle_coordinator_update
    self._percentage = self.coordinator.data.fan_speed
AttributeError: 'FanStatusMiot' object has no attribute 'fan_speed'
2023-05-29 08:05:04 ERROR (MainThread) [homeassistant] Error doing job: Task exception was never retrieved
Traceback (most recent call last):
  File "/usr/src/homeassistant/homeassistant/helpers/update_coordinator.py", line 134, in _handle_refresh_interval
    await self._async_refresh(log_failures=True, scheduled=True)
  File "/usr/src/homeassistant/homeassistant/helpers/update_coordinator.py", line 265, in _async_refresh
    update_callback()
  File "/usr/src/homeassistant/homeassistant/components/xiaomi_miio/fan.py", line 956, in _handle_coordinator_update
    self._percentage = self.coordinator.data.fan_speed
AttributeError: 'FanStatusMiot' object has no attribute 'fan_speed'
2023-05-29 08:05:19 ERROR (MainThread) [homeassistant] Error doing job: Task exception was never retrieved
Traceback (most recent call last):
  File "/usr/src/homeassistant/homeassistant/helpers/update_coordinator.py", line 134, in _handle_refresh_interval
    await self._async_refresh(log_failures=True, scheduled=True)
  File "/usr/src/homeassistant/homeassistant/helpers/update_coordinator.py", line 265, in _async_refresh
    update_callback()
  File "/usr/src/homeassistant/homeassistant/components/xiaomi_miio/fan.py", line 956, in _handle_coordinator_update
    self._percentage = self.coordinator.data.fan_speed
AttributeError: 'FanStatusMiot' object has no attribute 'fan_speed'
2023-05-29 08:05:34 ERROR (MainThread) [homeassistant] Error doing job: Task exception was never retrieved
Traceback (most recent call last):
  File "/usr/src/homeassistant/homeassistant/helpers/update_coordinator.py", line 134, in _handle_refresh_interval
    await self._async_refresh(log_failures=True, scheduled=True)
  File "/usr/src/homeassistant/homeassistant/helpers/update_coordinator.py", line 265, in _async_refresh
    update_callback()
  File "/usr/src/homeassistant/homeassistant/components/xiaomi_miio/fan.py", line 956, in _handle_coordinator_update
    self._percentage = self.coordinator.data.fan_speed
AttributeError: 'FanStatusMiot' object has no attribute 'fan_speed'
2023-05-29 08:05:49 ERROR (MainThread) [homeassistant] Error doing job: Task exception was never retrieved
Traceback (most recent call last):
  File "/usr/src/homeassistant/homeassistant/helpers/update_coordinator.py", line 134, in _handle_refresh_interval
    await self._async_refresh(log_failures=True, scheduled=True)
  File "/usr/src/homeassistant/homeassistant/helpers/update_coordinator.py", line 265, in _async_refresh
    update_callback()
  File "/usr/src/homeassistant/homeassistant/components/xiaomi_miio/fan.py", line 956, in _handle_coordinator_update
    self._percentage = self.coordinator.data.fan_speed
AttributeError: 'FanStatusMiot' object has no attribute 'fan_speed'
2023-05-29 08:06:04 ERROR (MainThread) [homeassistant] Error doing job: Task exception was never retrieved
Traceback (most recent call last):
  File "/usr/src/homeassistant/homeassistant/helpers/update_coordinator.py", line 134, in _handle_refresh_interval
    await self._async_refresh(log_failures=True, scheduled=True)
  File "/usr/src/homeassistant/homeassistant/helpers/update_coordinator.py", line 265, in _async_refresh
    update_callback()
  File "/usr/src/homeassistant/homeassistant/components/xiaomi_miio/fan.py", line 956, in _handle_coordinator_update
    self._percentage = self.coordinator.data.fan_speed
AttributeError: 'FanStatusMiot' object has no attribute 'fan_speed'
2023-05-29 08:06:19 ERROR (MainThread) [homeassistant] Error doing job: Task exception was never retrieved
Traceback (most recent call last):
  File "/usr/src/homeassistant/homeassistant/helpers/update_coordinator.py", line 134, in _handle_refresh_interval
    await self._async_refresh(log_failures=True, scheduled=True)
  File "/usr/src/homeassistant/homeassistant/helpers/update_coordinator.py", line 265, in _async_refresh
    update_callback()
  File "/usr/src/homeassistant/homeassistant/components/xiaomi_miio/fan.py", line 956, in _handle_coordinator_update
    self._percentage = self.coordinator.data.fan_speed
AttributeError: 'FanStatusMiot' object has no attribute 'fan_speed'
2023-05-29 08:06:34 ERROR (MainThread) [homeassistant] Error doing job: Task exception was never retrieved
Traceback (most recent call last):
  File "/usr/src/homeassistant/homeassistant/helpers/update_coordinator.py", line 134, in _handle_refresh_interval
    await self._async_refresh(log_failures=True, scheduled=True)
  File "/usr/src/homeassistant/homeassistant/helpers/update_coordinator.py", line 265, in _async_refresh
    update_callback()
  File "/usr/src/homeassistant/homeassistant/components/xiaomi_miio/fan.py", line 956, in _handle_coordinator_update
    self._percentage = self.coordinator.data.fan_speed
AttributeError: 'FanStatusMiot' object has no attribute 'fan_speed'
2023-05-29 08:06:49 ERROR (MainThread) [homeassistant] Error doing job: Task exception was never retrieved
Traceback (most recent call last):
  File "/usr/src/homeassistant/homeassistant/helpers/update_coordinator.py", line 134, in _handle_refresh_interval
    await self._async_refresh(log_failures=True, scheduled=True)
  File "/usr/src/homeassistant/homeassistant/helpers/update_coordinator.py", line 265, in _async_refresh
    update_callback()
  File "/usr/src/homeassistant/homeassistant/components/xiaomi_miio/fan.py", line 956, in _handle_coordinator_update
    self._percentage = self.coordinator.data.fan_speed
AttributeError: 'FanStatusMiot' object has no attribute 'fan_speed'
2023-05-29 08:07:04 ERROR (MainThread) [homeassistant] Error doing job: Task exception was never retrieved
Traceback (most recent call last):
  File "/usr/src/homeassistant/homeassistant/helpers/update_coordinator.py", line 134, in _handle_refresh_interval
    await self._async_refresh(log_failures=True, scheduled=True)
  File "/usr/src/homeassistant/homeassistant/helpers/update_coordinator.py", line 265, in _async_refresh
    update_callback()
  File "/usr/src/homeassistant/homeassistant/components/xiaomi_miio/fan.py", line 956, in _handle_coordinator_update
    self._percentage = self.coordinator.data.fan_speed
AttributeError: 'FanStatusMiot' object has no attribute 'fan_speed'
2023-05-29 08:07:19 ERROR (MainThread) [homeassistant] Error doing job: Task exception was never retrieved
Traceback (most recent call last):
  File "/usr/src/homeassistant/homeassistant/helpers/update_coordinator.py", line 134, in _handle_refresh_interval
    await self._async_refresh(log_failures=True, scheduled=True)
  File "/usr/src/homeassistant/homeassistant/helpers/update_coordinator.py", line 265, in _async_refresh
    update_callback()
  File "/usr/src/homeassistant/homeassistant/components/xiaomi_miio/fan.py", line 956, in _handle_coordinator_update
    self._percentage = self.coordinator.data.fan_speed
AttributeError: 'FanStatusMiot' object has no attribute 'fan_speed'
2023-05-29 08:07:34 ERROR (MainThread) [homeassistant] Error doing job: Task exception was never retrieved
Traceback (most recent call last):
  File "/usr/src/homeassistant/homeassistant/helpers/update_coordinator.py", line 134, in _handle_refresh_interval
    await self._async_refresh(log_failures=True, scheduled=True)
  File "/usr/src/homeassistant/homeassistant/helpers/update_coordinator.py", line 265, in _async_refresh
    update_callback()
  File "/usr/src/homeassistant/homeassistant/components/xiaomi_miio/fan.py", line 956, in _handle_coordinator_update
    self._percentage = self.coordinator.data.fan_speed
AttributeError: 'FanStatusMiot' object has no attribute 'fan_speed'
2023-05-29 08:07:49 ERROR (MainThread) [homeassistant] Error doing job: Task exception was never retrieved
Traceback (most recent call last):
  File "/usr/src/homeassistant/homeassistant/helpers/update_coordinator.py", line 134, in _handle_refresh_interval
    await self._async_refresh(log_failures=True, scheduled=True)
  File "/usr/src/homeassistant/homeassistant/helpers/update_coordinator.py", line 265, in _async_refresh
    update_callback()
  File "/usr/src/homeassistant/homeassistant/components/xiaomi_miio/fan.py", line 956, in _handle_coordinator_update
    self._percentage = self.coordinator.data.fan_speed
AttributeError: 'FanStatusMiot' object has no attribute 'fan_speed'
2023-05-29 08:07:55 WARNING (MainThread) [homeassistant.components.http] The 'base_url' option near /config/configuration.yaml:8 is deprecated, please remove it from your configuration
